Workbook
Name Arhitectura_Calculatoarelor_AC_2C_P03__Vălean: 'AN I'!$C$6
Name Arhitectura_Calculatoarelor_AC_2C_P03__Vălean: #REF!
Name Arhitectura_Calculatoarelor_AC_2C_P03__Vălean: #REF!
Name Arhitectura_Calculatoarelor_AC_2C_P03__Vălean: #REF!

Sheet ANUNT
C3: Orar / Timetable Secția de Automatică și Informatică Aplicată, Semestrul I, Facultatea de Automatică și Calculatoare
H5: Anul universitar 2026-2027
D7: Actualizat azi / Last Updated | N7: 26.10.2026, ora 09:25
C17: Vă rugăm, în PRIMELE 2 SAPTĂMÂNI ale SEMESTRULUI, verificați ZILNIC orarul afișat pe paginile web: https://ac.utcluj.ro sau http://aut.utcluj.ro. Este posibil sa sufere in continuare modificari. | O17: Please, in the FIRST 2 WEEKS of the SEMESTER, check DAILY the schedule displayed on the web pages: https://ac.utcluj.ro or http://aut.utcluj.ro. It is possible that it will continue to undergo changes.
E24: Sapt. / weeks 2026-2027 | J24: Legenda Sali / Rooms
E25: Saptamani didactice | J25: 200 - 214 | M25: cladirea AC Observator etaj 2 | S25: 2 Observatorului Street 2nd floor
D26: impar | E26: 1 | F26: 28 sept - 2 oct | J26: 6, 7 | M26: cladirea AC Observator parter | S26: 2 Observatorului Street P
D27: par | E27: 2 | F27: 5 - 9 oct | J27: 301 - 310 | M27: cladirea AC Observator etaj 3 | S27: 2 Observatorului Street 3rd floor
D28: impar | E28: 3 | F28: 12 - 16 oct | J28: 505 | M28: cladirea AC Observator etaj 5 | S28: 2 Observatorului Street 5th floor
D29: par | E29: 4 | F29: 19 - 23 oct | J29: E04 | M29: str. Baritiu 26-28, corp A (cladirea din spate) | S29: 26-28 Gh. Baritiu Street, | V29: the building inside the backyard
D30: impar | E30: 5 | F30: 26 - 30 oct | J30: 329 | M30: str. Baritiu 26-28, la parter
D31: par | E31: 6 | F31: 2 - 6 noi | J31: 40, F, 356, E15, E17, D21, D22, D11, D12, G1, G2, G6, 320(CEL), 329(FEC) | M31: cladirea AC str. Baritiu 26-28 | S31: 26-28 Gh. Baritiu Street
D32: impar | E32: 7 | F32: 8 - 13 noi
D33: par | E33: 8 | F33: 16 - 20 noi | J33: P03 | M33: cladirea AC noua (Sport) str. Baritiu 26 cu proiector | S33: 26-28 Gh. Baritiu Street, the building inside the backyard
D34: impar | E34: 9 | F34: 23 - 27 noi
D35: par | E35: 10 | F35: 2 - 4 dec | J35: Amf. D01, Amf. D03, Amf. D04 | M35: Str. Dorobantilor 71-73 | S35: 71-73 Dorobantilor Street, the building in the backyard
D36: impar | E36: 11 | F36: 7 - 11 dec
D37: par | E37: 12 | F37: 14 - 18 dec
E38: Vacanta 21 dec - 3 ian | J38: 16b, 26b, 36 | M38: cladirea AC str. Baritiu 26 | S38: 26-28 Gh. Baritiu Street
D39: impar | E39: 13 | F39: 4 - 8 ian | J39: s3.5 si s4.1 | M39: cladirea Somes Stanga, etaj 3, respectiv etajul 4, str. Baritiu 26 | S39: 26-28 Gh. Baritiu Street
D40: par | E40: 14 | F40: 11 - 15 ian | J40: H11, H21 | M40: cladirea Somes Dreapta, etaj 1, str. Baritiu 26 | S40: 26-28 Gh. Baritiu Street
J41: A2, B2, 152, 192, 197, 211(LS), 216(LS) | M41: cladirea Constructii str. Baritiu 25 | S41: 25 Gh. Baritiu Street
C42: Cum se interpreteaza! Exemplu. | J42: BT 203, BT 6.01(Lab Bosch), BT 6.02, BT 6.03, BT 6.04, BT 6.05 BT 7.01, BT 7.02, | M42: GH Baritiu 6-8 | S42: 6-8 Gh. Baritiu Street
J43: EM2 (S 2) | M43: cladirea turn str. Daicoviciu 15 | S43: 15 Daicoviciu Street, tower building
J44: Aula inst., I204, I205 - curs; I109, I110 - sem | M44: B-dul 21 Decembrie 1989 nr.128-130 | S44: 128-130, 21 decembrie 1989 Street
J46: C11, C12, C13, C03, C02, C01, A12 | M46: Str. Dorobantilor 71-73 | S46: 71-73 Dorobantilor Street, the building in the backyard
C47: 8-10 | D47: SCPC L 304
K48: D1, D2 | M48: cladire galbena de la poarta | S48: D1,D2 yellow building near the front gate
C49: 10-12 | E49: MP L 308 | K49: D3 | M49: cladirea alba din curte pe stanga | S49: D3 white building on the left
J50: 467, 479 | M50: Daicoviciu 15, etaj 1
J51: Sport | M51: Complex de Natație POLITEHNCA, str.Splaiul Independentei, f.n. | S51: Swimming complex POLITEHNICA, Splaiul Independentei Street, wihtout number
J55: G114, G112, M201, E112, C408 | M55: B-dul Muncii 103-105 (fac. Constructii de Masini)
J56: bazin Olimpic | M56: http://www.utcluj.ro/studenti/piscina.php http://www.utcluj.ro/servicii/piscina.php
C58: Link-uri utile/Useful links
E59: Link harta → | F59: http://maps.google.com/maps/ms?ie=UTF&msa=0&msid= 108437463130149962130.000490d9c7f3605ac5e63 | K59: ¬ Map | Q59: Link varianta pdf
E60: Transport public → | F60: https://ratuc.ro/ | K60: ¬ Public Transport Facilities
E61: Site-ul UTCN → | F61: https://www.utcluj.ro | K61: ¬ UTCN Web Page
E62: Bilbioteca online → | F62: https://www.utcluj.ro/biblioteca/ | K62: ¬ Online Library
C63: Lista de telefoane in interiorul UTCN → | F63: https://www.utcluj.ro/telefoane/ | K63: ¬ List of phone numbers inside TUCN

Sheet AN I
B1: ORAR AN I AUTOMATICA ȘI INFORMATICĂ APLICATA, SEMESTRUL I, AN UNIVERSITAR 2026-2027
B3: ORA | C3: SERIA I - A | O3: SERIA II - B | W3: ORA
A4: ZI | C4: 30111 | G4: 30112 | K4: 30113 | O4: 30114 | S4: 30115 | X4: ZI
C5: 1 | E5: 2 | G5: 1 | I5: 2 | K5: 1 | M5: 2 | O5: 1 | Q5: 2 | S5: 1 | U5: 2
A6: LUNI | B6: 8-10 | C6: Bazele Sistemelor Computationale BSC 2C F (D. Gota) | O6: Algebra liniara AL 2C 356 (V. Pop) | W6: 8-10 | X6: LUNI
B8: 10-12 | G8: AL S 467 | K8: AM S BT 6.02 | O8: Bazele Sistemelor Computationale BSC 2C 356 (A. Pop) | W8: 10-12
B10: 12-14 | K10: AL S BT 6.02 | O10: Analiză matematică AM 2C 356 (A. Novac) | W10: 12-14
B12: 14-16 | C12: LS S 467 (Fr) | S12: LS S E15 (Ger) | W12: 14-16
B14: 16-18 | C14: Intalnire cu indrumatorul de an amf. F (Roxana Rusu-Both) | W14: 16-18
B16: 18-20 | W16: 18-20
B18: 20-22 | C18: Psihologia educatiei PE 2C P03 (D. Stanciu) | W18: 20-22
A20: MARŢI | B20: 8-10 | C20: Circuite electronice liniare CEL 2C Aula Inst. (A. Grama) | W20: 8-10 | X20: MARŢI
B22: 10-12 | C22: Programarea calculatoarelor si limbaje de programare PCLP 2C Aula Inst. (R. Itu) | Q22: BSC L 309 | S22: BSC L 310 | W22: 10-12
B24: 12-14 | C24: Analiză matematică AM 2C Aula Inst. (D. Inoan) | O24: BSC L 309 | U24: BSC L 310 | W24: 12-14
B26: 14-16 | K26: CEL S BT 7.01 | W26: 14-16
E27: CEL S BT 7.01
B28: 16-18 | G28: CEL S BT 7.01 | S28: FIZICA L192 | W28: 16-18
Q29: CEL S BT 7.01
B30: 18-20 | O30: FIZICA L192 | S30: CEL S E15 | W30: 18-20
B32: 20-22 | O32: Intalnire cu indrumatorul de an H11 (Vlad Mihaly) | W32: 20-22
A34: MIERC. | B34: 8-10 | G34: PCLP L 206 | I34: BCS L 310 | K34: BCS L 309 | O34: PCLP L 205 | U34: FIZICA L192 | W34: 8-10 | X34: MIERC.
B36: 10-12 | C36: BCS L 309 | G36: BCS L 310 | I36: PCLP L 206 | M36: FIZICA L192 | Q36: PCLP L 205 | S36: CEL | V36: L 320 | W36: 10-12
S37: L 320 | V37: CEL
B38: 12-14 | C38: PCLP L 206 | E38: BCS L 309 | O38: CEL | R38: L 320 | S38: AL S BT 7.01 | W38: 12-14
O39: L 320 | R39: CEL
B40: 14-16 | E40: PCLP L 206 | G40: AM S D11 | O40: AL S BT 7.01 | W40: 14-16
B42: 16-18 | I42: FIZICA L192 | S42: PCLP L 205 | W42: 16-18
B44: 18-20 | E44: FIZICA L192 | U44: PCLP L 205 | W44: 18-20
B46: 20-22 | W46: 20-22
A48: JOI | B48: 8-10 | C48: AL S BT 6.02 | M48: PCLP L 210 | O48: AM S E15 | W48: 8-10 | X48: JOI
B50: 10-12 | C50: AM S E15 | K50: PCLP L 210 | M50: BCS L 308 | W50: 10-12
B52: 12-14 | K52: FIZICA L192 | W52: 12-14
B54: 14-16 | C54: Algebra liniara AL 2C Amf. D21(C. Todea) | O54: Fizica FIZ 2C H11 (L. Pop) | W54: 14-16
B56: 16-18 | C56: Fizica FIZ 2C Amf. D21 (L. Pop) | O56: Circuite electronice liniare CEL 2C H11 (A. Grama) | W56: 16-18
B58: 18-20 | O58: Programarea calculatoarelor si limbaje de programare PCLP 2C H11 (I. Costin) | W58: 18-20
B60: 20-22 | W60: 20-22
A62: VINERI | B62: 8-10 | C62: CEL | F62: L 320 | G62: FIZICA L192 | O62: LS S BT 7.01 (En) | S62: AM S D11 | W62: 8-10 | X62: VINERI
C63: L 320 | F63: CEL
B64: 10-12 | G64: CEL | J64: L 320 | K64: LS S BT 7.01(En) | Q64: FIZICA L192 | W64: 10-12
G65: L 320 | J65: CEL
...

Sheet AN I En
B2: YEAR I, AIA EN, ACADEMIC YEAR 2026-2027 | K2: =ANUNT!N7 -> 26.10.2026, ora 09:25
A4: DAY | B4: TIME | C4: 30311 (ISA) | G4: 30312 (ISA) | K4: 30313 (ISA) | M4: 30313 (ISA) | O4: TIME | AC4: DAY
C5: 1 | E5: 2 | G5: 1 | I5: 2 | K5: 1 | M5: 1 | P5: v1 - old
A6: MONDAY | B6: 8-10 | C6: MA S BT 6.02 | I6: Phys. L 192 | O6: 8-10 | P6: 8-10 | Q6: MA S BT 6.01 | Y6: CA L 302 | AC6: MONDAY
B8: 10-12 | C8: Fundamentals of Computational Systems FCS 2C F (H. Vălean) | O8: 10-12 | P8: 10-12 | T8: L 192 | U8: MA S BT 6.01 | Y8: Phys. | AA8: CA L 302
T9: Phys. | Y9: L 192
B10: 12-14 | C10: Computer Programming and Programming Languages CPPL 2C F (T. Sanislav) | O10: 12-14 | P10: 12-14 | R10: L 192 | U10: LEC S BT 5.01 | W10: Phys. | X10: LEC S | Y10: MA S S2(EM2)
R11: Phys. | W11: L 192 | X11: BT 5.01
B12: 14-16 | C12: Physics PH 2C F (R. Fechete) | O12: 14-16 | P12: 14-16 | Q12: Physics PH 3C D21 (R. Fechete)
B14: 16-18 | O14: 16-18 | P14: 16-18
E15: LEC S 467 | Q15: Computer Programming and Programming Languages CPPL 2C D21 (T. Sanislav)
B16: 18-20 | O16: 18-20 | P16: 18-20
B18: 20-22 | C18: Psihologia educatie PE 2C P03 (D. Stanciu) | O18: 20-22 | P18: 20-22 | Q18: Psihologia educatie PE 2C P03 (D. Stanciu)
A20: TUESDAY | B20: 8-10 | C20: FCS L 309 | E20: FCS L 310 | K20: FL S BT 7.01 (LS) | O20: 8-10 | AC20: TUESDAY
B22: 10-12 | G22: LEC S BT 6.02 | O22: 10-12
M23: LEC S BT 6.02
B24: 12-14 | G24: CPPL L BT 6.03 | O24: 12-14
B26: 14-16 | I26: CPPL L BT 6.03 | O26: 14-16
B28: 16-18 | O28: 16-18
B30: 18-20 | C30: Study Advisor Meeting (Anastasios Natsakis ) Amf D03 | O30: 18-20
B32: 20-22 | O32: 20-22
P33: vi - solutionat partial
A34: WEDNESDAY | B34: 8-10 | C34: FL S BT 7.01 (LS) | K34: LA S 467 | O34: 8-10 | P34: FL S BT 7.01 | T34: CA L 310 | AC34: WEDNESDAY
B36: 10-12 | C36: LA S 467 | G36: FL S BT 7.01 (LS) | M36: CPPL L BT 6.03 | O36: 10-12 | R36: CPPL L BT 6.03 | T36: FL S BT 7.01 (LS) | Z36: CA L 310
B38: 12-14 | C38: CPPL L BT 6.03 | G38: LA S S2 467 | K38: MA S BT 6.02 | O38: 12-14 | P38: CPPL L BT 6.03 | U38: L 192 | X38: CA L 310 | Z38: Phys.
U39: Phys. | Z39: L 192
B40: 14-16 | G40: MA S 467 | O40: 14-16 | T40: LA S S2 E17 | Z40: CPPL L BT 6.03
B42: 16-18 | G42: Phys. L 192 | O42: 16-18
B44: 18-20 | C44: Phys. L 192 | O44: 18-20
B46: 20-22 | O46: 20-22
P47: vi - solutionat
A48: THURSDAY | B48: 8-10 | C48: Linear Electronic Circuits LEC 2C H21 (G. Oltean) | O48: 8-10 | P48: Linear Electronic Circuits LEC 2C D21 (G. Oltean) | AC48: THURSDAY
B50: 10-12 | C50: Mathematical Analysis MA 2C H21 (V.D. Popa) | O50: 10-12 | P50: Mathematical Analysis I (Differential Calculus) MA 2C D21 (V.D. Popa)
B52: 12-14 | C52: Linear Algebra LA 2C H21 (I.R. Peter) | O52: 12-14 | P52: Linear Algebra, Analytical and Differential Geometry LAADG 2C D21 (I.R. Peter)
B54: 14-16 | K54: LEC L BT 1.03 | M54: Phys. L 192 | O54: 14-16 | P54: LA S BT 6.01 | T54: LEC L BT 1.03
J55: LEC L BT 1.03 | W55: LEC L BT 1.03
B56: 16-18 | G56: LEC L BT 1.03 | K56: FCS L BT 6.05 | O56: 16-18 | P56: LEC L BT 1.03 | X56: LA S BT 6.01
N57: LEC L BT 1.03 | S57: LEC L BT 1.03
B58: 18-20 | C58: LEC L BT 1.03 | O58: 18-20 | X58: LEC L BT 1.03
F59: LEC L BT 1.03 | AA59: LEC L BT 1.03
...

Sheet AN II
B1: ORAR AN II AUTOMATICA ȘI INFORMATICĂ APLICATA , SEMESTRUL I, AN UNIVERSITAR 2026-2027
Y2: v2
A3: ZI | B3: ORA | C3: SERIA I - A | V3: ORA | W3: ZI | Y3: ORA | Z3: SERIA I
C4: 30121 | G4: 30124 | K4: 30122 | O4: 30123 | U4: Recontractare | Z4: 30121 | AD4: 30122 | AH4: 30123 | AL4: 30124
G5: 1 | I5: 2 | K5: 1 | M5: 2 | O5: 1 | Q5: 2 | S5: 2 | Z5: 1 | AB5: 2 | AD5: 1 | AF5: 2 | AH5: 1 | AJ5: 2
A6: LUNI | B6: 8-10 | C6: ED L 303 | G6: ED L 303 | O6: MP L BT 6.03 | V6: 8-10 | W6: LUNI | Y6: 8-10 | Z6: Electronică digitală ED 2C D21 (G.Harja)
B8: 10-12 | K8: MP L BT 6.03 | M8: ED L 303 | R8: H01 | V8: 10-12 | Y8: 10-12 | Z8: Calcul numeric CN 2C D21 (I. Gavrea)
R9: MT L
B10: 12-14 | C10: Metode numerice MN 2C D21 (M.Birou) | V10: 12-14 | Y10: 12-14 | Z10: Modelarea proceselor MP 2C D21 (Cistelecan)
B12: 14-16 | C12: Modelarea proceselor MP 2C D21 (D. Morar) | V12: 14-16 | Y12: 14-16 | AD12: PA L 203 | AF12: ED L 303
B14: 16-18 | C14: Electronică digitală ED 2C D21 (I. Nașcu) | V14: 16-18 | Y14: 16-18 | AF14: PA L 203 | AH14: ED L 303 | AJ14: ASDN L 211 | AL14: MP L G6
B16: 18-20 | V16: 18-20 | Y16: 18-20 | AD16: ED L 303 | AH16: ASDN L 211 | AJ16: PA L 203 | AN16: MP L G6
A18: MARŢI | B18: 8-10 | E18: ED L 303 | I18: MP L G6 | L18: 197 | M18: MN L | Q18: CN L | S18: PA L 203 | V18: 8-10 | W18: MARŢI | Y18: 8-10 | Z18: ASDN L 211
B20: 10-12 | C20: PA L 203 | E20: ASDN L 211 | L20: MN L | M20: 197 | N20: H01 | Q20: 197 | S20: ED L 303 | V20: 10-12 | Y20: 10-12 | Z20: ED L 303 | AD20: Sport | AL20: PA L 203 | AN20: ASDN L 211
N21: MT L
B22: 12-14 | C22: ASDN L 211 | E22: PA L 203 | G22: ASDN L 211 | I22: ED L 302 | O22: ED L 303 | V22: 12-14 | Y22: 12-14 | AH22: H01 | AL22: ASDN L 211 | AN22: PA L 203
AH23: MT L
B24: 14-16 | C24: Germana GE 2C - E15 (M. Tripon) | V24: 14-16 | Y24: 14-16 | Z24: Germana GE 2C - F (M. Tripon) | AD24: Germana GE 2C - F | AK24: H01 | AL24: Germana GE 2C - F | AN24: Germana GE 2C - F (M. Tripon)
AK25: MT L
B26: 16-18 | P26: 197 | S26: MN L | V26: 16-18 | Y26: 16-18 | AB26: ASDN L 211 | AD26: CN L | AF26: H01 | AG26: 197
AF27: MT L
B28: 18-20 | I28: PA L 203 | M28: ASDN L 211 | P28: MN L | S28: 197 | V28: 18-20 | Y28: 18-20 | AD28: 197 | AE28: H01 | AG28: CN L
AE29: MT L
A30: MIERC. | B30: 8-10 | C30: MP L C01 | S30: ASDN L 211 | V30: 8-10 | W30: MIERCuri | Y30: 8-10 | Z30: H01 | AA30: 197 | AB30: CN L | AH30: PA L 203 | AL30: ED L 302
Z31: MT L
B32: 10-12 | E32: MP L C01 | K32: PA L 203 | V32: 10-12 | Y32: 10-12 | AA32: CN L | AB32: 197 | AC32: H01 | AN32: ED L 302
AC33: MT L
B34: 12-14 | I34: H01 | K34: ASDN L 211 | S34: MP L C01 | V34: 12-14 | Y34: 12-14 | AH34: Sport
I35: MT L
B36: 14-16 | C36: Sport | H36: H01 | M36: MP L C01 | O36: ASDN L 211 | V36: 14-16 | Y36: 14-16 | Z36: PA L 203 | AL36: Sport
H37: MT L
B38: 16-18 | C38: MN L | F38: 197 | K38: ED L 303 | O38: PA L 203 | V38: 16-18 | Y38: 16-18 | AB38: PA L 203 | AI38: 197 | AJ38: CN L | AN38: H01
AN39: MT L
B40: 18-20 | C40: 197 | D40: H01 | F40: MN L | M40: PA L 203 | V40: 18-20 | Y40: 18-20 | AI40: CN L | AJ40: 197 | AM40: H01
D41: MT L | AM41: MT L
B42: 20-22 | C42: Intalnire cu indrumatorul de an (Adela Pop ) D21 | V42: 20-22 | Y42: 20-22
A44: JOI | B44: 8-10 | G44: CN L | J44: 197 | O44: H01 | V44: 8-10 | W44: JOI
O45: MT L
B46: 10-12 | G46: 197 | J46: CN L | K46: Sport | T46: H01 | V46: 10-12
T47: MT L
...

Sheet AN II En
B1: YEAR II, AIA EN, ACADEMIC YEAR 2026-2027 | J1: =ANUNT!N7 -> 26.10.2026, ora 09:25
A2: ZI | B2: ORA | C2: 30321 | G2: 30322 | K2: 30323 | M2: ORA | N2: ZI
C3: 1 | E3: 2 | G3: 1 | I3: 2 | K3: 1
A4: MONDAY | B4: 8-10 | C4: AD L 203 | E4: LD L 211 | I4: NM L 197 | K4: MA L H.41 | M4: 8-10 | N4: MONDAY
B6: 10-12 | C6: LD L 211 | E6: AD L 203 | L6: NM L 197 | M6: 10-12
B8: 12-14 | M8: 12-14
B10: 14-16 | C10: Logic Design 2C (V. Miclea) H11 | M10: 14-16
B12: 16-18 | C12: Digital Electronics DE 2C - (Harja) H11 | M12: 16-18
B14: 18-20 | C14: Numerical methods NM 2C (Patrulescu) P03 | M14: 18-20
A16: TUESDAY | B16: 8-10 | C16: Algorithms Design AD 2C (R. Portase) amf. D03 | M16: 8-10 | N16: TUESDAY
B18: 10-12 | C18: Process Modelling PM 2C (D. Moga) amf. D03 | M18: 10-12
B20: 12-14 | C20: Measurements and Transducers MA (R Holonec) amf. D03 | M20: 12-14
B22: 14-16 | M22: 14-16
B24: 16-18 | C24: Study Advisor Meeting (Alexandru George Berciu ) D03 | M24: 16-18
B26: 18-20 | M26: 18-20
A28: WEDNESDAY | B28: 8-10 | C28: H.41 | G28: Sport | M28: 8-10 | N28: WEDNESDAY
C29: MA L
B30: 10-12 | F30: H.41 | M30: 10-12
F31: MA L
B32: 12-14 | C32: Sport | G32: NM L 197 | I32: H.41 | K32: PM L 505 | M32: 12-14
I33: MA L
B34: 14-16 | E34: PM L 505 | H34: H.41 | M34: 14-16
H35: MA L
B36: 16-18 | C36: English 2 EN 2C (C. Policsek) H11 | M36: 16-18
B38: 18-20 | M38: 18-20
B40: 20-22 | M40: 20-22
A41: THURSDAY | B41: 8-10 | E41: DE L 303 | K41: Sport | M41: 8-10 | N41: THURSDAY
B43: 10-12 | C43: DE L 303 | M43: 10-12
B45: 12-14 | C45: NM L 197 | I45: DE L 303 | M45: 12-14
B47: 14-16 | F47: NM L 197 | G47: LD L 211 | K47: DE L 303 | M47: 14-16
B49: 16-18 | G49: DE L 303 | I49: LD L 211 | K49: AD L 203 | M49: 16-18
B51: 18-20 | I51: AD L 203 | K51: LD L 211 | M51: 18-20
B53: 20-22 | C53: Basics of Quantum Information 2C 40 fac | M53: 20-22
A54: FRIDAY | B54: 8 - 10 | C54: PM L 505 | G54: AD L 203 | M54: 8 - 10 | N54: FRIDAY
B56: 10-12 | G56: PM L 505 | M56: 10-12
B58: 12-14 | I58: PM L 505 | M58: 12-14
B60: 14-16 | M60: 14-16
B62: 16-18 | M62: 16-18
B64: 18-20 | M64: 18-20
C68: Pedagogie II 2C : joi, ora 8-10 sau 10-12 sau 12-14, sala 206 str. Daicoviciu 15, Blocul Turn, etaj II Pedagogie 2S: marti, ora 16-18 sala E15; miercuri, ora 16-18 sala E15, ora 18-20 amf. D21.
...

Sheet AN III
B1: ORAR AN III AIA, SEMESTRUl I, AN UNIVERSITAR 2026-2027 | S1: =ANUNT!N7 -> 26.10.2026, ora 09:25
A3: ZI | B3: ORA | C3: SERIA I - A | K3: SERIA II - B | X3: ORA | Y3: ZI
C4: 30131 | G4: 30132 | K4: 30133 | O4: 30134 | S4: 30135 | W4: Recontractare (seria I - A)
C5: 1 | E5: 2 | G5: 1 | I5: 2 | K5: 1 | M5: 2 | O5: 1 | Q5: 2 | S5: 1 | U5: 2 | AA5: 1
A6: LUNI | B6: 8-10 | E6: IRA L 305 | G6: SDED L 302 | I6: TS L 505 | O6: TS S E15 | X6: 8-10 | Y6: LUNI
M7: TS E15 S
B8: 10-12 | C8: IRA L 305 | E8: TS L 505 | G8: IS C13 | X8: 10-12
G9: P | U9: TS E15 S
B10: 12-14 | C10: EP L 305B | D10: 305B | I10: IS C13 | Q10: TS L 505 | U10: SBC L | V10: BT 6.01 | X10: 12-14
D11: EP P | I11: P | U11: BT 6.01 | V11: SBC P
B12: 14-16 | E12: IS C13 | I12: EP L 305B | J12: 305B | M12: TS L 505 | S12: SBC L | T12: BT 6.01 | X12: 14-16
E13: P | J13: EP P | S13: BT 6.01 | T13: SBC P
B14: 16-18 | C14: IS C13 | I14: SDED L 310 | K14: SBC L | L14: BT 6.01 | O14: IRA L 305 | S14: IS L BT 6.05 | X14: 16-18
C15: P | K15: BT 6.01 | L15: SBC P
B16: 18-20 | C16: Intalnire cu indrumatorul de an - 356 ( Alexandru Codrean ) | K16: IS L BT 6.05 | Q16: SBC L | R16: BT 6.01 | X16: 18-20
Q17: BT 6.01 | R17: SBC P
B18: 20-22 | K18: Intalnire cu indrumatorul de an - 356 (Laurențiu Chifor) | X18: 20-22
A20: MARŢI | B20: 8-10 | E20: EP L 305B | F20: 305B | O20: TS L 505 | Q20: IS L BT 6.05 | S20: IRA L 305 | U20: SDED L 302 | W20: IS P C13 | X20: 8-10 | Y20: MARŢI
F21: EP P
B22: 10-12 | C22: TS L 505 | G22: EP L 305B | H22: 305B | M22: IS L BT 6.05 | U22: IRA L 305 | X22: 10-12
H23: EP P
B24: 12-14 | G24: IRA L 305 | K24: TS L 505 | O24: IS L BT 6.05 | W24: IS L C13 | X24: 12-14
B26: 14-16 | G26: TS L 505 | K26: IRA L 305 | O26: SBC L | P26: BT 6.01 | X26: 14-16
O27: BT 6.01 | P27: SBC P
B28: 16-18 | I28: IRA L 305 | M28: SBC L | N28: BT 6.01 | S28: SDED L 302 | X28: 16-18
M29: BT 6.01 | N29: SBC P
B30: 18-20 | C30: Instruire asistată de calculator IAC 1C / 1S 40 | K30: Instruire asistată de calculator IAC 1C / 1S | X30: 18-20
A32: MIERCURI | B32: 8-10 | G32: TS S BT 6.02 | K32: Identificarea Sistemelor IS 2C F (M. Șușcă) | X32: 8-10 | Y32: MIERCURI
E33: TS S BT 6.02
B34: 10-12 | C34: Identificarea Sistemelor IS 2C H11 (L. Busoniu) | K34: Teoria Sistemelor II TS 2C F (P. Dobra) | X34: 10-12
B36: 12-14 | C36: Teoria Sistemelor II TS 2C H11 (P. Dobra) | K36: Sisteme Dinamice cu Evenimente Discrete SDED 2C F (A. Aştilean) | X36: 12-14
B38: 14-16 | C38: Sisteme dinamice cu Evenimente Discrete SDED 2C H11 (A. Aştilean) | K38: Management si comunicare 2C D21 (V. Maier) | X38: 14-16
B40: 16-18 | C40: Management si comunicare 2C D21 (V. Maier) | K40: SDED L 309 | X40: 16-18
B42: 18-20 | M42: SDED L 309 | X42: 18-20
B44: 20-22 | X44: 20-22
A46: JOI | B46: 8-10 | E46: IS L C13 | L46: P | M46: IS BT 6.03 | Q46: IRA L 305 | S46: TS L BT 6.04 | U46: IS L BT 6.01 | X46: 8-10 | Y46: JOI
L47: IS BT 6.03 | M47: P
B48: 10-12 | C48: IS L C13 | M48: IRA L 305 | O48: IS P | U48: TS L BT 6.04 | X48: 10-12
O49: BT 6.03 | T49: IS P BT 6.03
B50: 12-14 | Q50: IS P | X50: 12-14
...

Sheet AN III En
B1: YEAR III, AIA EN, ACADEMIC YEAR 2026-2027 | G1: =ANUNT!N7 -> 26.10.2026, ora 09:25
A4: DAY | B4: TIME | C4: 30331 | G4: 30332 | K4: 30333 | M4: TIME | N4: DAY
C5: 1 | E5: 2 | G5: 1 | I5: 2 | K5: 1
A6: MONDAY | B6: 8-10 | C6: Power Electronics PE 2C 467 (C. Festila) | G6: Knowledge-based Systems KBS 2C D21 (R. Rusu-Both) | M6: 8-10 | N6: MONDAY
B8: 10-12 | C8: System theory II ST 2C D21 ( (M. Dobra) | M8: 10-12
B10: 12-14 | D10: c13 | E10: SI 2L C01 Dor. | G10: CE L 305 | K10: DSDE L 302 | M10: 12-14
D11: SI P
B12: 14-16 | C12: SI L C01 Dor. | F12: c13 | G12: DSDE L 302 | K12: CE L 305 | M12: 14-16
F13: SI P
B14: 16-18 | G14: ST L 505 | I14: DSDE L 302 | M14: 16-18
B16: 18-20 | I16: ST L 505 | M16: 18-20
A18: TUESDAY | B18: 8-10 | K18: SI L C01 Dor. | M18: 8-10 | N18: TUESDAY
J19: SI P C13
B20: 10-12 | I20: SI L C01 Dor. | K20: SI P | M20: 10-12
H21: SI P C13 | K21: C13
B22: 12-14 | G22: SI L C01 Dor. | M22: 12-14
B24: 14-16 | C24: Management and Comunication 2C D03 (V. Maier) | M24: 14-16
B26: 16-18 | C26: Economic Law EL 2C 40 (R. Cordos) | M26: 16-18
B28: 18-20 | C28: Instruire asistată de calculator IAC 1C/ 1S 40 | I28: KBS L/P BT6.01 | M28: 18-20
B30: 20-22 | M30: 20-22
A32: WEDNESDAY | B32: 8-10 | C32: Systems Identification SI 2C 356 (L.Busoniu) | M32: 8-10 | N32: WEDNESDAY
B34: 10-12 | C34: Control engineering I CE 2C 356 (C. Muresan) | M34: 10-12
B36: 12-14 | C36: Dynamical Systems with Discrete Events DSDE 2C 356 (C. Avram) | M36: 12-14
B38: 14-16 | E38: DSDE L BT 6.05 | M38: 14-16
B40: 16-18 | C40: DSDE L BT 6.05 | I40: CE L 305 | M40: 16-18
B42: 18-20 | E42: CE L 305 | M42: 18-20
B44: 20-22 | C44: Study Advisor Meeting 356 (Sorin Herle ) | M44: 20-22
A46: THURSDAY | B46: 8-10 | C46: PE L/P 305B | E46: ST L 505 | M46: 8-10 | N46: THURSDAY
B48: 10-12 | C48: ST L 505 | E48: PE L/P 305B | G48: KBS L BT 6.01 | M48: 10-12
B50: 12-14 | C50: CE L 305 | G50: KBS P BT 6.01 | K50: ST L 505 | M50: 12-14
B52: 14-16 | K52: ST S 505 | M52: 14-16
B54: 16-18 | G54: ST S 467 | K54: KBS L BT 6.01 | M54: 16-18
B56: 18-20 | C56: ST S 467 | K56: KBS P BT 6.01 ST | M56: 18-20
A58: FRIDAY | B58: 8-10 | M58: 8-10 | N58: FRIDAY
B60: 10-12 | M60: 10-12
B62: 12-14 | M62: 12-14
B64: 14-16 | C64: Automatică în aplicații industriale AAI (Emerson) 2C E15 (sapt. pară) | M64: 14-16
B66: 16-18 | M66: 16-18
B68: 18-20 | M68: 18-20
C71: Link varianta pdf

Sheet AN IV 
B1: ORAR AN IV AIA, SEMESTRUL I, AN UNIVERSITAR 2026-2027 | O1: =ANUNT!N7 -> 26.10.2026, ora 09:25
C3: Automatica - A | M3: Informatica aplicata - IA
A4: ZI | B4: ORA | C4: 30141 (A) | G4: 30142 (A) | K4: 30143 (A) | M4: 30144 (I) | Q4: 30145 (I) | U4: 30146 (I) | Y4: 30147 (I) | AA4: ORA | AB4: ZI
C5: 1 | E5: 2 | G5: 1 | I5: 2 | K5: 1 | M5: 1 | O5: 2 | Q5: 1 | S5: 2 | U5: 1 | W5: 2 | Y5: 1
A6: LUNI | B6: 8-10 | I6: SCR 2L C12 | K6: FD 4L S3.5 | M6: MP 4L 308 | O6: SCPC 4L 304 | S6: RC 4L 505B | Z6: s3.5 | AA6: 8-10 | AB6: LUNI
R7: SCD 2L G6
B8: 10-12 | C8: SCR 2L C12 | F8: C13 | N8: SCPC 4L 304 | P8: SCD 2L G6 | T8: MP 4L 308 | U8: SCD 2L G6 | V8: RC 4L 505B | Z8: FD 4L | AA8: 10-12
F9: SCR 2P
B10: 12-14 | M10: SCD 2L G6 | O10: RC 4L 505B | Q10: MP 4L 308 | S10: SCPC 4L 304 | T10: SCD 2L G6 | AA10: 12-14
B12: 14-16 | C12: Microsisteme şi Achiziţii de Date MAD 2C 356 (S. Folea) | N12: RC 4L 505B | P12: FD 4L s3.5 | R12: SCPC 4L 304 | W12: SCD 2L G6 | X12: MP 4L 308 | AA12: 14-16
B14: 16-18 | C14: Maşini Electrice şi Acţionări MEA 2C 356 (Hedesiu) | Q14: RC 4L 505B | AA14: 16-18
B16: 18-20 | C16: Etică și integritate academică 2C D21 (Peculea) | R16: Etică 2C D21 | V16: FD 4L s3.5 | W16: Etica | Z16: RC 4L 505B | AA16: 18-20
B18: 20-22 | AA18: 20-22
A20: MARŢI | B20: 8-10 | C20: Sisteme de Control Distribuit SCD 356 2C(O. Cuibus) | M20: SCR 2L C12 | U20: SCPC 4L 304 | AA20: 8-10 | AB20: MARŢI
B22: 10-12 | C22: Fiabilitate şi Diagnoză 2C FD 356 (L. Miclea) | O22: SCR 2L C12 | X22: SCPC 4L 304 | AA22: 10-12
B24: 12-14 | C24: SCPC 4L 304 | G24: FD 4L s3.5 | K24: SCR 2L C12 | M24: Fiabilitate şi Diagnoză FD 2C 356 (L. Miclea) | AA24: 12-14
B26: 14-16 | E26: MAD 4L | F26: SCPC 4L 304 | H26: C 13 | J26: FD 4L s3.5 | K26: SCR 2P | M26: Sisteme de Control Distribuit SCD 2C 356 (T. Leţia) | AA26: 14-16
H27: SCR 2P | K27: C13
B28: 16-18 | D28: FD 4L | E28: 303 | I28: SCR 2P | Q28: FD 4L S3.5 | S28: SCR 2L C12 | Z28: C13 | AA28: 16-18
I29: C13 | Z29: SCR 2P
B30: 18-20 | D30: s3.5 | S30: SCR 2P | X30: C13 | Y30: SCR 2L C12 | AA30: 18-20
S31: C13 | X31: SCR 2P | AD31: v1 - solved
B32: 20-22 | M32: Intalnire cu indrumatorul de an - amf. 40 (Marius Misaroș) | AA32: 18-20
AD33: v1 - solved
A34: MIERCURI | B34: 8-10 | C34: SCD 2L G6 | G34: MAD 4L 303 | I34: MEA 4L 7 | U34: MP 4L 308 | W34: RC 4L 505B | AA34: 8-10 | AB34: MIERCURI | AD34: MIERCURI | AE34: 8-10 | AF34: MAD L 303 | AL34: SCPC L 304 | AP34: RC 505B | AR34: SCD L G6 | AZ34: MP L 308 | BA34: SCD L G6 | BB34: FD L s3.5
L35: SCD 2L G6
B36: 10-12 | D36: MEA 4L 7 | H36: SCPC 4L 304 | J36: SCD 2L G6 | P36: MP 4L 308 | Y36: SCD 2L G6 | AA36: 10-12 | AE36: 10-12 | AK36: MAD L 303 | AN36: SCD L G6 | AO36: RC 505B | AU36: MP L 308 | BC36: SCPC L 304
AM37: SCD L G6
B38: 12-14 | E38: SCD 2L G6 | G38: SCD 2L G6 | K38: MAD 4L 303 | N38: C13 | AA38: 12-14 | AE38: 12-14 | AK38: SCD L G6 | AL38: FD L s3.5 | AN38: MP L 308 | AT38: SCD L G6
N39: SCR 2P
B40: 14-16 | J40: SCPC 4L | P40: C13 | Q40: SCR 2P | Z40: MP 4L 308 | AA40: 14-16 | AE40: 14-16 | AF40: SCR L C12 | AQ40: MP L 308 | BA40: SCPC L
J41: 304 | P41: SCR 2P | Q41: C13 | BA41: 304
B42: 16-18 | F42: s3.5 | Q42: SCR 2L C12 | U42: SCR 2P | W42: FD 4L s3.5 | AA42: 16-18 | AE42: 16-18 | AS42: C01 | AV42: SCR P | AX42: SCR L C12
U43: C13 | AS43: SCR P | AV43: C01
B44: 18-20 | C44: SCR 2P | F44: FD 4L | U44: SCR 2L C12 | Z44: SCPC 4L 304 | AA44: 18-20 | AE44: 18-20 | AN44: SCR L C12 | AQ44: SCPC L 304 | AX44: SCR P
C45: C13 | AX45: C01
B46: 20-22 | AA46: 20-22 | AE46: 20-22
A48: JOI | B48: 8-10 | E48: SCR 2L C12 | K48: MEA 4L 7 | N48: s3.5 | S48: FD 4L | AA48: 8-10 | AB48: JOI | AD48: JOI | AE48: 8-10 | AF48: MEA L 7 | AG48: FD L | AH48: SCR L C12 | AJ48: SCPC L | AN48: Sisteme de Conducere a Proceselor Continue SCPC 2C F (I. Naşcu)
B50: 10-12 | L50: SCPC 4L 304 | N50: FD 4L | S50: s3.5 | W50: SCR 2L C12 | AA50: 10-12 | AE50: 10-12 | AG50: s3.5 | AJ50: 304 | AK50: MEA L 7 | AL50: SCR L C12 | AN50: Sisteme de Conducere a Roboţilor SCR 2C F (C. Marcu)
B52: 12-14 | G52: SCR 2L C12 | M52: Sisteme de Conducere a Proceselor Continue SCPC 2C D04 (I. Naşcu) | AA52: 12-14 | AE52: 12-14 | AV52: SCPC L | AX52: FD L | BA52: s3.5
...

Sheet AN IV En
B1: YEAR IV, AIA EN, ACADEMIC YEAR 2024-2025 | L1: =ANUNT!N7 -> 26.10.2026, ora 09:25
C3: Automatica - A | J3: Informatica Aplicată - IA
A4: Day | B4: Time | C4: 30341 (A) | I4: 30342 (I) | M4: 30343 (I) | Q4: Time | R4: Day
C5: 1 | E5: 2 | G5: 2 | I5: 1 | K5: 2 | M5: 1 | O5: 2
A6: MONDAY | B6: 8-10 | E6: EMD 4L sala 7 OBS | Q6: 8-10 | R6: MONDAY
E7: 7 Obs
B8: 10-12 | D8: EMD 4L sala 7 OBS | Q8: 10-12
B10: 12-14 | M10: RCS 2P | P10: C12 | Q10: 12-14 | T10: RCS L C12
M11: C12 | P11: RCS 2P
B12: 14-16 | C12: Robot control systems RCS 2C amf. D03 (A. Natsakis) | Q12: 14-16 | T12: RCS 2P C12
W13: RCS 2P C12
B14: 16-18 | M14: RCS 2L C12 | Q14: 16-18
B16: 18-20 | O16: RCS 2L C12 | Q16: 18-20
B18: 20-22 | Q18: 20-22
A20: TUESDAY | B20: 8-10 | E20: RD 4L s3.5 | G20: CPC L 304 | K20: CN 4L 505B | Q20: 8-10 | R20: TUESDAY
B22: 10-12 | D22: RD 4L s3.5 | J22: CN 4L 505B | Q22: 10-12
B24: 12-14 | C24: Distributed control systems DCS 2C H11 (T.Leţia) | Q24: 12-14
B26: 14-16 | C26: Continuous plant control CPC 2C H11 (I. Naşcu) | Q26: 14-16
B28: 16-18 | O28: CN 4L | Q28: 16-18
O29: 505B
B30: 18-20 | H30: CN L 505B | N30: CN 4L | Q30: 18-20
N31: 505B | S31: v1
A32: WEDNESDAY | B32: 8-10 | C32: CPC 4L 304 | F32: C13 | G32: PM L 308 | I32: RD 4L s3.5 | K32: RCS 2L C12 | M32: PM 4L BT 6.05 | Q32: 8-10 | R32: WEDNESDAY | S32: RCS L C12 | V32: C13 | W32: PM L 308 | Y32: RD L s3.5 | AC32: PM L BT 6.05
F33: RCS 2P | V33: RCS 2P
B34: 10-12 | D34: MDA 4L 303 | E34: RCS 2L C12 | H34: RD L s3.5 | J34: C13 | K34: RCS 2P | N34: RD | P34: PM 4L BT 6.05 | Q34: 10-12 | S34: RCS 2P | U34: RCS L C12 | X34: RD L s3.5 | Z34: C13 | AB34: PM L BT 6.05 | AD34: RD
J35: RCS 2P | K35: C13 | N35: 4L s3.5 | S35: C13 | Z35: RCS 2P | AD35: L s3.5
B36: 12-14 | C36: RCS 2P | I36: RCS 2L C12 | K36: RD 4L s3.5 | O36: CPC 4L 304 | Q36: 12-14 | Y36: RCS L C12 | AA36: CPC L 304
C37: C13
B38: 14-16 | C38: RCS 2L C12 | E38: DCS 2L G6 | F38: MDA 4L 303 | H38: C13 | N38: DCS | P38: RD 4L s3.5 | Q38: 14-16 | U38: DCS 2L G6 | X38: C13 | AB38: RD L s3.5
H39: RCS 2P | N39: 2L G6 | X39: RCS 2P | AD39: DCS 2L G6
B40: 16-18 | C40: DCS 2L G6 | F40: ` | I40: DCS 2L G6 | Q40: 16-18 | S40: DCS 2L G6 | Y40: DCS 2L G6
B42: 18-20 | I42: DCS 2P G6 | Q42: 18-20 | Y42: DCS 2P G6
L43: DCS 2L G6 | AB43: DCS 2P G6
A44: THURSDAY | B44: 8-10 | E44: CPC 4L 304 | G44: DCS P 310 | K44: PM 4L BT 6.05 | Q44: 8-10 | R44: THURSDAY | W44: DCS P 310 | AA44: PM L BT 6.05 | AB44: 310 DCS 2P | AC44: DCS 2P 310
B46: 10-12 | J46: PM 4L BT 6.05 | O46: DCS | P46: G6 | Q46: 10-12 | S46: DCS 2P 310 | T46: CPC L 304 | V46: 310 | Z46: PM L BT 6.05
O47: 2L G6 | P47: DCS 2P | V47: DCS 2P
B48: 12-14 | C48: Marketing H11 ( V. Maier) / Personal and professional development 2C 356 | Q48: 12-14 | S48: Marketing H11 ( V. Maier)/ Personal and professional development 2C 356
B50: 14-16 | C50: DCS 2P G6 | F50: G6 | K50: CPC 4L 304 | Q50: 14-16 | S50: Robot control systems RCS 356 2C (A. Natsakis)
F51: DCS 2P
B52: 16-18 | L52: DCS 2P G6 | M52: DCS 2P | P52: 310 | Q52: 16-18 | W52: DCS 2L G6 | Y52: DCS 2P 309
...

Sheet MASTER AN I
A1: A ȘI INFORMATICĂ APLICATA, SEMESTRUL I, AN UNIVERSITAR 2026-2027 | V1: =ANUNT!N7 -> 26.10.2026, ora 09:25
A3: ZI | B3: ORA | C3: MASTER An I
C4: Contolul Avansat al Proceselor (CAP) | I4: ICAF | M4: Inf. Apl. în Ing. Sist. Complexe (IAISC) | S4: Informatica Aplicata (IA) | W4: CPS
C5: 31111 (2 semigrupe) | G5: 31112 | I5: 31211 (1 semigrupa) | M5: 31311 (2 semigrupe) | Q5: 31312 | S5: 31411 (2 semigrupe) | W5: 31511 (2 semigrupe) | AA5: 31512 (1 semigrupa)
A6: LUNI | B6: 8-12
B8: 12-16
B10: 16-18 | S10: AB 2L C01
W11: Mathematical Foundations MF (Peter Radu) 1C BT 7.01 (17-18)
B12: 18-20 | C12: MA 4S 467(4h) | E12: MA 4S 467(4h) | I12: SSTR 4C H11 | M12: SSTR 4C H11 | S12: AB 4C C01 | U12: AB 2L C01 | W12: MF 2L BT 7.01
D13: MA 2C H11 | F13: MA 2C H11 | J13: MA 2C H11 | Y13: MF 2L BT 7.01
B14: 20-22 | H14: MA 2C H11 | K14: MA 2C H11 (18-20) | O14: MA 2C H11
A16: MARŢI | B16: 8-14
B18: 14-16
B20: 16-18 | S20: TAS P 308 | U20: TAS P 308 | AA20: ES 2L BT 6.02 2,4,6,8,10,12,14
B22: 18-20 | C22: SI 4C 303 | D22: Si 4L 303 | E22: SI 4C 303 | F22: Si 4L 303 | G22: SI 4C 304 | I22: SSTR 2L 310 (18-20) | M22: MA 4S 467 (4h) | N22: SSTR 2L 310 | O22: MA 4S 467 (4h) | U22: CP 4L 308 spt. 3,7,9,13(18-22) | W22: Evolutive Systems ES (Valean) 4C BT 7.01 | X22: ES 2L BT 7.01 2,4,6,8,10,12,14 | Y22: Evolutive Systems ES (Valean) 4C BT 7.01 | AA22: Evolutive Systems ES (Valean) 4C BT 7.01
B24: 20-22 | D24: spt. 2,6,10,14 (2h) | F24: spt. 4,8,12,14 (2h) | H24: MA 4S 467 (4h) | J24: MA 4S 467 (4h) | K24: SSTR 2L 310 | L24: MA 4S 467 (4h) | P24: SSTR 2L 310 | R24: MA 4S 467 (4h) | T24: CP 4L 308 sapt. 4,8.10,13(20-22) | Z24: ES 2L BT 7.01 2,4,6,8,10,12,14
A26: MIERC. | B26: 8-14
B28: 14-16
B30: 16-18 | M30: EFAC 2P C13 | U30: ***TAS 4L 308
AA31: RM 1L S BT 7.01 (17-18)
B32: 18-20 | C32: APD 4L 305B 1,5,9,13 (2h) | E32: APD 4L 305B 3,7,11,13 (2h) | I32: TIA 4C D11 | K32: TIA 4C D11 | M32: TIA 4C D11 | O32: TIA 4C D11 | P32: EFAC 2C C13 | Q32: TIA 4C D11 | R32: EFAC 2C C13 | T32: *TAS 4L 308 | W32: Research Methods RM (Dulf E.) 2C BT 7.01
B34: 20-22 | D34: APD 4C 305B | F34: APD 4C 305B | H34: APD 4C 305B | J34: RI 4C D11 | L34: RI 4L 302 2,6,10,14(2h) | N34: EFAC 2C C13 | P34: EFAC 2P C13 | R34: EFAC 2P C13 | S34: EP P 302 | U34: EP P 302 | W34: RM 1L S bt 7.01 | AA34: MF 2L 7.02
Y35: RM 1L S bt 7.01
A36: JOI | B36: 8-14
B38: 14-16
B40: 16-18
B42: 18-20 | C42: SA 4L 303 1,5,9,13(2h) | E42: SA 4L 303 3,7,11,13 (2h) | G42: SI 4L 304 1,5,9,13 (2h) | I42: TIA 4L s3.5 sapt. 1,5,9,13(2h), intre orele 18-22 | K42: TIA 4L s3.5 sapt. 3,7,11,13(2h) | M42: EFAC 4L C13 st. 3,7,11,13(2h) | O42: EFAC 4L C13 1,5,9,13(2h) | Q42: EFAC 4L C13 3,7,11,13 (2h) | R42: SSTR 2L 310 | S42: TAS 4C BT 7.02 | W42: Machine Learning ML (Miclea V.) 2C BT 7.01
B44: 20-22 | D44: SA 4C 303 | F44: SA 4C 303 | H44: SA 4C 303 | J44: RI 4L 302 intre orele 18-22 , 2,6,8,12 (2h) | L44: RI 4C 302 | N44: TIA 4L s3.5 2,6,10,14(2h) | P44: TIA 4L s3.5 spt. 4,8,12,14(2h) | U44: CP 4C BT 7.02 | V44: CP 4C BT 7.02 | W44: ML 2L BT 7.01 | Y44: ML2L BT 7.01 | AA44: ML2L BT 6.05
A46: VINERI | B46: 8-12
B48: 12-14
B50: 14-16
B52: 16-18 | S52: EP 2C 302 | U52: EP 2C 302
B54: 18-20 | G54: SA 4L 304 3,7,11,13 (2h) | R54: TIA 4L s3.5 | U54: EP 4L 303
B56: 20-22 | H56: APD 4L 305B 2,6,10,14 (2h) | R56: spt. 2,6,10,14(2h) | T56: EP 4L 303
A58: SAMBATA | B58: 9-11
B60: 11-13
B62: 13-15
B64: 15-17
B66: 17-19
I70: Anul universitar 2026-2027 | M70: LEGENDA (NOTATII)
...

Sheet MASTER AN II
A1: AUTOMATICĂ ȘI INFORMATICĂ APLICATĂ, AN II , SEMESTRUL I, AN UNIVERSITAR 2026-2027 | O1: =ANUNT!N7 -> 26.10.2026, ora 09:25
A3: ZI | B3: ORA | C3: MASTER An II
C4: (CAP) | G4: (ICAF) | K4: (IAISC) | O4: Informatica Aplicata (IA) | U4: CPS
C5: 31161 ( 2 semigrupe) | G5: 31261 (1 semigrupa) | K5: 31361 (2 semigrupe) | O5: 31461(2 semigrupe) | S5: 31462 (1 semigrupa) | U5: 31511 (2 semigrupe)
A6: LUNI | B6: 8-14
B8: 14-16 | C8: CI L sapt. 3 (16-18) sapt. 5,11, 13 (14-18) sala s3.5 CI CURS SAPT. 9 s35 (18-22)
B10: 16-18
B12: 18-20 | E12: CI L sapt. 3 (18-20) sapt. 5 ,11, 13 (18-22) sala s3.5 CI CURS SAPT. 9 s35 (18-22) | G12: MD 4L 304 sapt. 3, 7, 11, 13(2h) | H12: CAD 4L M201 | I12: CAD 4L M201 in sapt 1,5,9 (18-22), in sapt. 13(18-20) | K12: SR 4C 303 | M12: SR 4C 303 | O12: PA 4C 6.02 | Q12: PA 4C 6.02 | S12: PA 4C 6.02 | U12: Emerging Control Systems for Industry 5.0 505 (I. Birs)
B14: 20-22 | H14: in sapt 2,6,10 (18-22), in sapt. 14(18-20) | L14: IA 4C BT 6.02 | N14: IA 4C BT 6.02 | P14: SSATR 4L 310 săpt. 2,6,10,14(2h) | R14: SSATR 4L 310 săpt.4,8,12,14(2h) | T14: CEBD 4L BT 6.03 sapt. 2,6,10, 14(20-22) | U14: ECSI 5.0 1L 505
W15: ECSI 5.0 1L 505
A16: MARŢI | B16: 8-12
B18: 12-16
B20: 16-18
B22: 18-20 | C22: CI 4C D21 sapt. 1, 3, 5,9,11,13 | E22: CI 4C D21 sapt. 1, 3, 5,9,11,13 | G22: SI 4C 303 | I22: SI 4C 304 | J22: MD L 303 | K22: IA 4L 309 | M22: IA 4L 309 | O22: MP 4C BT 6.04 | Q22: MP 4C BT 6.04 | S22: MP 4C BT 6.04 | U22: Reinforcement Learning Amf D01 (L. Bușoniu)
B24: 20-22 | D24: VA 4C D21 | F24: VA 4C D21 | J24: 2,6,10,14(2h) | K24: 1,5,9,13 (2h) | L24: VA 4C D21 | M24: 3,7,11,13 (2h) | N24: VA 4C D21 | P24: CEBD 4C BT 6.03 | R24: CEBD 4C BT 6.03 | T24: CEBD 4C BT 6.03 | U24: RI 1L amf. D01
W25: RI 1L amf. D01
A26: MIERCURI | B26: 8-14
B28: 14-16
B30: 16-18
B32: 18-20 | C32: SH 4C EM2 | E32: SH 4C EM2 | G32: SI 4L 303 in sapt. 1,5,9 (18-22), in sapt 13 (18 -20) | I32: SI 4L 304 ,sapt. 3,7,11 (18-22) in sapt. 13 (20-22) | K32: SE 2L 310 2h 1,3,5,7,9,11 13 intre 18-20 | O32: MP 4L Bt 6.04 3,5,9,13(2h) | U32: Human-Robot Interaction Amf D04 (T. Natsakis)
B34: 20-22 | D34: SH 4L 505 spt. 2, 6, 10, 14 (2h) | F34: SH 4L 505 sapt. 4, 8, 12, 14 (2h) | H34: MCP 4L C01 2, 6,10, 14 (18-20) | J34: MCP 4L C01 4, 8,12, 14 (20-22) | K34: ` | L34: SR 4L 303 sapt. 2,6,10, 14(2h 18-20) | M34: SE 2L 310 1,3,5,7,9,11 13 intre 20-22 | N34: SR 4L 303 sapt. 4,8,12, 14(2h 20-22) | R34: MP 4L Bt 6.04 4,8,12,14(2h) | T34: SSATR 4L 310 săpt. 2,6,10,14(2h) | U34: HRI 1L C12
W35: HRI 1L C12
A36: JOI | B36: 8-14
B38: 14-16
T39: CEBD P BT 6.03
B40: 16-18 | O40: CEBD P Bt 6.03
R41: CEBD P BT 6.03
B42: 18-20 | C42: MCP 4C 310 | E42: MCP 4C 310 | G42: MCP 4C 310 | I42: MCP 4C 309 | K42: VA 4L 505 sapt. 1,5,9, 13(2h) | M42: VA 4L 505 sapt. 3,7,11, 13(2h) | O42: SSATR 4C D21 | Q42: SSATR 4C D21 | S42: SSATR 4C D21 | U42: Dependability of Cyber-Physical Systems 4C BT 6.02 (L. Miclea) (sapt,impara, 18-22)
B44: 20-22 | D44: VA 4L 505 2,6,10, 14 (2h) | F44: VA 4L 505 4, 8,12,14 (2h) | H44: MD 4C 304 | J44: MD 4C 304 | L44: SE 4C D21 | N44: SE 4C D21 | P44: CEBD 4L BT 6.03 sapt. 2, 6,10,14(2h) | R44: CEBD 4L BT 6.03 sapt. 4,8,12, 14(20-22) | T44: MP 4L BT 6.04 4,8,12,14(2h)
A46: VINERI | B46: 8-14
B48: 14-16 | S48: PA P 308
B50: 16-18 | O50: PA P 308 | U50: DCPS 2L 309
R51: PA P 308 | U51: 1,3,5,7,9,11,13, intre 16-18)
B52: 18-20 | C52: MCP 4L C01 1,5,9, 13(2h) | D52: ETICA | E52: MCP 4L C01 3,7,11, 13 (2h) | F52: ETICA | G52: CAD 4C M201 | H52: ETICA 2C P03 | I52: CAD 4C M201 | J52: ETICA 2C P03 | K52: ETICA 2C P03 (sapt. para) (Peculea) | M52: ETICA 2C P03 (sapt. para) | O52: PA 4L 308 1,5,9,13(2h) | P52: ETICA | Q52: PA 4L 308 3,7,11,13 (2h) | R52: ETICA | S52: ETICA 2C P03 (sapt. para) | V52: ETHICS 2C BT 6.02 | W52: DCPS 2L 309 1,3,5,7,9,11,13, intre 18-20) | X52: ETHICS
B54: 20-22 | T54: PA 4L 308 2,6,10,12 (2h)
C58: Anul universitar 2026-2027
C59: Saptamani didactice | F59: Acronim
C60: 1 | D60: 28 sept - 2 oct | F60: VA | G60: Viziune artificiala(N. Stroia)
C61: 2 | D61: 5 - 9 oct | F61: MD | G61: Monitorizare şi diagnoză(R.CRISAN)
C62: 3 | D62: 12 - 16 oct | F62: MCP | G62: Managementul si controlul proceselor(E.DULF)
...

Sheet Sali Curs no real time update
A1: Semestrul I anul universitar 2026-2027
C2: BARITIU | J2: DOROBANTILOR
A3: Zi | B3: Ora | C3: 40 | D3: F | E3: 356 | F3: P03 | G3: H11 | H3: H21 | I3: D21 | J3: Aula | K3: D01 | L3: D03 | M3: Ora | N3: Zi
C4: 130 | D4: 100 | E4: 60 | F4: 249 | G4: 80 | H4: 80 | I4: 110 | K4: 135 | L4: 135
A5: LUNI | B5: 8:-10: | C5: 4r | D5: 1r aut a | E5: 1r aut b | F5: 4r | G5: 1r | I5: 3e aut | J5: no | K5: 2ea | L5: 1ea | M5: 8:-10: | N5: LUNI
B6: 10:-12: | C6: 4r | D6: 1e aut | E6: 1r aut b | F6: 4r | G6: 1r | I6: 3e aut | J6: no | K6: 2ea | L6: 1ea | M6: 10:-12:
B7: 12:- 14: | C7: 2r | D7: 1e aut | E7: 1r aut b | F7: 4r | G7: 1r | I7: 2r aut | J7: no | K7: 2ea | L7: 1ea | M7: 12:- 14:
B8: 14-16 | C8: 2r | D8: 1e aut | E8: 4r aut | F8: 3e | G8: 2e aut | I8: 2r aut | J8: no | K8: 3r | L8: 4e aut | M8: 14-16
B9: 16-18 | C9: 2r | D9: 1r aut | E9: 4r aut | F9: 3e | G9: 2e aut | I9: 2r aut | J9: no | K9: 3r | L9: 3e | M9: 16-18
B10: 18-20 | C10: 2r | D10: 1M | E10: 3r aut | F10: 2e aut | G10: 1M aut | I10: 4r aut | J10: no | K10: 3r | L10: 3e | M10: 18-20
B11: 20-22 | C11: 3r aut | D11: 1M (s) / | E11: 3r aut | F11: 1r+e aut opt | G11: 1M aut | M11: 20-22
A12: MARŢI | B12: 8:-10: | D12: 4e | E12: 4r aut | F12: no | G12: 4e | I12: 2r | J12: 1r aut a | K12: 1r | L12: 2e aut | M12: 8:-10: | N12: MARŢI
B13: 10:-12: | C13: 3r | D13: 4e | E13: 4r aut | F13: no | I13: 2r | J13: 1r aut a | K13: 1r | L13: 2e aut | M13: 10:-12:
B14: 12:- 14: | C14: 3r | D14: 4e | E14: 4r aut | F14: no | G14: 4e aut | I14: 2r | J14: 1r aut a | K14: 3e | L14: 2e aut | M14: 12:- 14:
B15: 14-16 | C15: 3e | D15: 4e | E15: 4r aut | F15: no | G15: 4e aut | I15: 3r | J15: no | K15: 1r | L15: 3e aut | M15: 14-16
B16: 16-18 | C16: 3e+aut LE | D16: 4e | E16: 3r??? | F16: no | G16: 1M(s) | I16: 3r | J16: no | L16: 2e aut | M16: 16-18
B17: 18-20 | C17: 3re aut C+S | D17: 1M | F17: no | G17: Bosch AD | I17: 2M aut | J17: no | K17: 2M aut | L17: 1e aut | M17: 18-20
B18: 20-22 | C18: 4r aut cons | D18: 1M (s) / | E18: 3r+e | G18: 1r aut | I18: 2M aut | K18: 2M aut | M18: 20-22
A19: MIERC. | B19: 8:-10: | C19: 2eb | D19: 3r aut b | E19: 3e aut | F19: no | I19: 2ea | J19: no | K19: 3r | L19: 1eb | M19: 8:-10: | N19: MIERC.
B20: 10:-12: | C20: 2eb | D20: 3r aut b | E20: 3e aut | F20: no | G20: 3r aut a | I20: 2ea | J20: no | K20: 3r | L20: 1eb | M20: 10:-12:
B21: 12:- 14: | C21: 2eb | D21: 3r aut b | E21: 3e aut | F21: no | G21: 3r aut a | I21: 2ea | J21: no | K21: 3r | L21: 1eb | M21: 12:- 14:
B22: 14-16 | C22: 2eb | D22: 4r | E22: 4r | F22: no | G22: 3r aut a | I22: 3r aut Man | J22: no | K22: 4r | L22: 4r | M22: 14-16
B23: 16-18 | C23: 2+1M (IP) | D23: 4r | E23: 4r | F23: no | G23: 2e aut LS | I23: 3r aut Man | J23: no | K23: 4r | L23: 4r | M23: 16-18
B24: 18-20 | C24: 2+1M (IP) | D24: 4r | E24: 4r | F24: no | G24: 1M | I24: Ped AC S | J24: no | K24: 4r | L24: 4r | M24: 18-20
B25: 20-22 | C25: 2+1M (IP) | D25: 4r+e | E25: 3e aut | G25: 1r+e opt | I25: 2r aut | M25: 20-22
A26: JOI | B26: 8:-10: | C26: 2M DS | E26: 4e | F26: no | G26: 4e | H26: 1e aut | I26: 3e | J26: 3e | K26: 1r | L26: 1ea | M26: 8:-10: | N26: JOI
B27: 10:-12: | C27: 2r | D27: 1r MS (s) | E27: 4e | F27: no | G27: 4e | H27: 1e aut | I27: 3e | J27: 3e | K27: 1r | L27: 1ea | M27: 10:-12:
B28: 12:- 14: | C28: 2r | D28: 4e | E28: 4e cs+4e aut | F28: no | G28: 4e cs + 4e aut Marketing | H28: 1e aut | I28: 3e | J28: 3e | K28: 1r | L28: 1ea | M28: 12:- 14:
B29: 14-16 | C29: 2r | D29: 4e | E29: 4e aut Dezv | F29: 1r | G29: 1r aut b | I29: 1r aut b | J29: no | K29: 4r aut | L29: 2r aut | M29: 14-16
B30: 16-18 | C30: 2r | D30: 2r | E30: 1M AIV | F30: 1r | G30: 1r aut b | I30: 1r aut b | J30: no | K30: 4r aut | L30: 2r aut | M30: 16-18
B31: 18-20 | C31: 2r | D31: 4e aut | E31: 1M AIV(s) | F31: 1r | G31: 1r aut b | I31: 2M aut | J31: no | K31: 4r aut | M31: 18-20
B32: 20-22 | C32: 2r+e aut fac. + 1M AIV | E32: 2M | I32: 2M aut | M32: 20-22
A33: VINERI | B33: 8:-10: | C33: 3r | D33: 3r aut b | E33: 3r aut a | F33: 2eb | G33: 4e aut | I33: 4r aut | J33: no | L33: 1eb | M33: 8:-10: | N33: VINERI
B34: 10:-12: | C34: 3r | D34: 3r aut b | E34: 3r aut a LE | F34: 2eb | G34: 4e aut | I34: 4r aut | J34: no | K34: 4r | L34: 1eb | M34: 10:-12:
B35: 12:- 14: | C35: 3r | D35: 3r aut b LE | E35: 3r aut a | F35: 2eb | G35: 4e aut | I35: 2r aut | J35: no | K35: 4r | L35: 1eb | M35: 12:- 14:
B36: 14-16 | C36: no | D36: 3r | E36: 1r aut fac. S | F36: 4r aut Mark | G36: LS prima sapt | I36: 2r aut EN | J36: 4r | M36: 14-16
B37: 16-18 | C37: no | D37: 2r | E37: 1r aut fac. C | F37: 4r aut Dezv | I37: 2r +2r aut FR | J37: 4r | M37: 16-18
B38: 18-20 | C38: no | F38: / 2M etica | M38: 18-20
B39: 20-22 | M39: 20-22
C40: 40 | D40: F | E40: 356 | F40: P03 | G40: H11 | H40: H21 | I40: D21 | J40: Aula | K40: D1 | L40: D2

Sheet Sali Seminar no real time updat
E1: Sali diponibile pentru semestrul I anul universitar 2026-2027
E2: Comune | K2: CALC Baritiu | N2: CALC Dorobantilor | Q2: AUT | R2: AUT
A3: Zi | B3: Ora | C3: CALC CM0 | D3: AUT CM | E3: D11 | F3: D12 | G3: 467 | H3: E15 | I3: E17 | J3: S2(EM2) | K3: BT 5.01 | L3: BT 5.02 | M3: BT 7.02 | N3: M1 | O3: M2 | P3: M3 | Q3: BT 7.01 | R3: BT 6.02 | S3: Sport | T3: Ora | U3: Zi
C4: 30 | D4: 30 | E4: 36 | F4: 36 | G4: 35 | H4: 36 | I4: 24 | J4: 25 | K4: 30 | L4: 30 | M4: 30 | N4: 30 | O4: 30 | P4: 30 | Q4: 30 | R4: 30
A5: LUNI | B5: 8:-10: | E5: no | F5: no | G5: 3e C KBS | H5: 3r aut (TS) | K5: 1r AM (s) | L5: 2e SME (s) | R5: 1e aut MA | T5: 8:-10: | U5: LUNI
B6: 10:-12: | E6: no | F6: no | G6: 1r aut AL | H6: /3r aut (TS) | K6: 1r AM (s) | L6: 2e SME (s) | M6: 2e SME (s) | O6: 1e AL | P6: 1e LS (s) | Q6: 1e AM | R6: 1r aut AM | T6: 10:-12:
B7: 12:- 14: | E7: no | F7: no | I7: 1r LS | L7: 2e SME (s) | M7: 2e SME (s) | N7: 1e SM | O7: 1e AL | P7: 1e LS (s) | R7: 1r aut AL | T7: 12:- 14:
B8: 14-16 | E8: no | F8: no | G8: 1r aut (Fr) | H8: 1r aut G | J8: el | L8: 1r PC (s) | M8: 1r AM (s) | N8: 1e CP | O8: 1e LS (s) | Q8: 1 GE | T8: 14-16
B9: 16-18 | E9: no | F9: no | G9: /1e aut LEC | H9: 1M(s) | I9: 4e TD (p) | J9: el | L9: 1M DS | Q9: 1M aut CPS | T9: 16-18
B10: 18-20 | E10: no | F10: no | G10: 1M aut/ | I10: 4e TD (p) | J10: el | K10: 1M AV | L10: 1M DS | Q10: 1M aut CPS | R10: 2M AUT CPS | T10: 18-20
B11: 20-22 | G11: 1M aut/ | K11: 1M(s) AV | Q11: 1M aut CPS | R11: 2M AUT CPS | T11: 20-22
A12: MARŢI | B12: 8:-10: | E12: 1e AM | H12: 1e AL | K12: 1M DS | Q12: 1e aut LS | T12: 8:-10: | U12: MARŢI
B13: 10:-12: | F13: 1e SM | G13: 1e AL | H13: 1e LS (s) | J13: 1e LS (s) | K13: 1M DS | L13: 2r/e(s) AF | M13: 1r AM (s) | R13: 1e aut LEC | T13: 10:-12:
B14: 12:- 14: | G14: 1e FL-germ | J14: 1e aut MA | M14: 1r AM (s) | O14: 1e LS (s) | S14: 2r aut | T14: 12:- 14:
B15: 14-16 | E15: no | F15: no | G15: 1r AF (s) | H15: 2r+2e+aGe | M15: 1r AM (s) | O15: 1r PC (s) | Q15: 1r aut CEL | S15: 2e aut | T15: 14-16
B16: 16-18 | E16: no | F16: no | H16: Ped AC S | K16: 1M AV | L16: 2M(s) | M16: 2M(s) | O16: 1r PC (s)/ | Q16: 1r aut CEL | R16: 1M aut CPS | S16: 2r aut | T16: 16-18
B17: 18-20 | E17: no | F17: no | G17: 1M aut | H17: 1r aut CEL/ | K17: 1M AV(s) | L17: 2M | M17: 2M | Q17: 1M aut CPS | R17: 2M IA | T17: 18-20
B18: 20-22 | G18: 1M aut | H18: 1M AV | Q18: 1M aut CPS | R18: 2M IA | T18: 20-22
A19: MIERC. | B19: 8:-10: | E19: no | F19: no | G19: 1e aut LA | H19: 1r AM (s) | K19: 1M DS | L19: 1r AL (s) | M19: 2r MSI (s) | P19: 1e AL | Q19: 1e aut LS | R19: 3r aut (TS) | T19: 8:-10: | U19: MIERC.
B20: 10:-12: | E20: no | F20: no | G20: 1e aut LA | H20: 1r AM (s) | K20: 1M DS | L20: 2r MSI (s) | M20: 2r MSI (s) | N20: 1e SM | P20: 1e AL | Q20: 1e aut LS | T20: 10:-12:
B21: 12:- 14: | E21: no | F21: no | G21: 1e aut LA | H21: 1r MS (s) | K21: 1M DS | L21: 2r MSI (s) | M21: 2r MSI (s) | N21: 1e SM | O21: 1e AM | Q21: 1r aut AL | R21: 1e aut MA | S21: 2r aut | T21: 12:- 14:
B22: 14-16 | E22: 1r aut AM | F22: 2e (s) FA | G22: 1e aut MA | H22: 2M AIV(s) | L22: 2r MSI (s) | M22: 1r AM (s) | N22: 1e CP | O22: 1e AM | Q22: 1r aut AL | T22: 14-16
B23: 16-18 | E23: 1M(s) | G23: 1r AL (s) | H23: Ped AC S | I23: 1M | K23: 1M AV | N23: 1e CP / | Q23: 1M aut CPS | S23: 2r aut | T23: 16-18
B24: 18-20 | E24: 1M aut | F24: 1MC (s) | G24: 1r AL (s) | H24: 2M | I24: 2M DS | J24: 2M aut/ | K24: 1M AV(s) | Q24: 1M aut CPS | R24: 2M AUT CPS | T24: 18-20
B25: 20-22 | E25: 1M aut | F25: 1MC | H25: 2M(s) | I25: 2M DS (L) | J25: 2M aut/ | Q25: 1M aut CPS | R25: 2M AUT CPS | T25: 20-22
A26: JOI | B26: 8:-10: | E26: no | F26: no | H26: 1r aut AM | J26: el | K26: 1M DS | R26: 1r aut AL | S26: 2e aut | T26: 8:-10: | U26: JOI
B27: 10:-12: | E27: no | F27: no | H27: 1r aut AM | J27: el | K27: 1M DS | M27: 2r MSI (s) | S27: 2r aut/2e aut | T27: 10:-12:
B28: 12:- 14: | E28: no | F28: no | G28: 1r MS (s) | J28: el | K28: 1r LS (s) | M28: 2r MSI (s) | S28: 2r aut | T28: 12:- 14:
B29: 14-16 | H29: 2r(s) AF | J29: el | O29: 1r PC (s) | T29: 14-16
B30: 16-18 | E30: 1M | F30: 1M | G30: 3e aut (TS)/ | H30: 1M | I30: 1MC | J30: el | K30: 1M AV | L30: 1M | O30: 1r PC (s) / | T30: 16-18
B31: 18-20 | E31: 1M | F31: 1M | G31: 3e aut (TS)/ | H31: 1M(s) | I31: 1M | J31: el | K31: 1M AV(s) | L31: 1M | M31: 1M aut | Q31: 1M aut CPS | R31: 2M aut cPS | T31: 18-20
B32: 20-22 | H32: postuniv | M32: 1M aut | Q32: 1M aut CPS | R32: 2M aut cPS | T32: 20-22
A33: VINERI | B33: 8:-10: | E33: 1r aut AM | F33: 1r AM (s) | G33: 1r MS (s) | H33: 2r MSI (s) | I33: 2M CSC | J33: el | M33: 1r AM (s) | N33: 1M DS | Q33: 1r aut LS | T33: 8:-10: | U33: VINERI
B34: 10:-12: | E34: 4e aut C | F34: 1r AM (s) | G34: 1r MS (s) | H34: 1r LS (s) | J34: el | K34: 1r LS (s) | L34: 1r AL (s) | M34: 1r AM (s) | Q34: 1r aut LS | T34: 10:-12:
B35: 12:- 14: | E35: 4e aut C | F35: 2e | H35: Matematica | J35: el | Q35: 1r aut LS | S35: 2r aut | T35: 12:- 14:
B36: 14-16 | E36: no | F36: no | H36: 3r aut emerson | J36: el | T36: 14-16
B37: 16-18 | E37: no | F37: no | J37: el | T37: 16-18
B38: 18-20 | E38: no | F38: no | H38: 2M | J38: el | R38: 2M aut cPS | T38: 18-20
B39: 20-22 | T39: 20-22
C40: CALC CM0 | D40: AUT CM | E40: D11 | F40: D12 | G40: 467 | H40: E15 | I40: E17 | J40: S2(EM2) | K40: BT 5.01 | L40: BT 5.02 | M40: BT 7.02 | N40: M1 | O40: M2 | P40: M3 | Q40: BT 7.01 | R40: BT 6.02 | S40: Sport
...

Sheet Sali Lab. AIA
A1: Săli laborator utilizate pentru discipline din cadrul planurilor de invatamant ale sectiei Automatica si Informatica Aplicată, semestrul I anul universitar 2026-2027
A3: Zi | B3: ORa | C3: 302 | D3: 303 | E3: 304 | F3: 305 | G3: 305 B | H3: 308 | I3: 309 | J3: 310 | K3: 505 | L3: 505B | M3: S35 | N3: G6 | O3: G2 | P3: C01 | Q3: C11 | R3: C12 | S3: C13 | T3: sala 7 Obs | U3: BT 6.01 Lab Bosch | V3: BT 6.03 | W3: BT 6.04 | X3: BT 6.05 | Y3: 320 (BCE) | Z3: 329 (LEC) | AA3: 192 (Fizica) | AB3: ORA | AC3: Zi
C4: Observatorului 2 (langa Sigma) | M4: Baritiu 26-28 (Fac. AC) | P4: Dorobantilor 71-73 | U4: BT, Baritiu 6-8
A5: LUNI | B5: 8:-10: | C5: 3r SDED | D5: 2r ED | E5: 4r SCPC | F5: 3r IRA | H5: 4r MP | K5: 3r TS | L5: 4r RC | M5: 4r FD | N5: /4r SCD | R5: 4r SCR | T5: 4e EMD | V5: 2r MP | AB5: 8:-10: | AC5: LUNI
B6: 10:-12: | D6: 2r ED | E6: 4r SCPC | F6: 3r IRA | H6: 4r MP | K6: 3r TS | L6: 4r RC | M6: 4r FD | N6: 4r SCD | R6: 4r SCR | S6: 3r IS(P)/4r SCR (P) | T6: 4e EMD | V6: 2r MP | AB6: 10:-12:
B7: 12:- 14: | C7: 3e DSDE | E7: 4r SCPC | F7: 3e CE | G7: 3r EP | H7: 4r MP | K7: 3r TS | L7: 4r RC | M7: /4r FD | N7: 4r SCD | P7: 3e SI | R7: 4e RCS P | S7: 3r IS(P)/3e SI P | U7: 3r SBC L/P | AA7: 1e aut | AB7: 12:- 14:
B8: 14-16 | C8: 3e DSDE | E8: 4r SCPC | F8: 3e CE | G8: 3r EP | H8: 4r MP | K8: 3r TS | L8: 4r RC | M8: 2M/4r FD | N8: 4r SCD/ | P8: 3e SI | S8: 3r IS(P)/3e SI P | U8: 3r SBC L/P | AA8: 1e aut | AB8: 14-16
B9: 16-18 | C9: 3e DSDE | F9: 3r IRA | J9: 3r SDED | K9: 3e ST | L9: 4r RC | M9: 2M/4r FD | P9: /1M | R9: 4e RCS | S9: 3r IS(P)/ | U9: 3r SBC L/P | X9: 3r IS | AA9: |1raut | AB9: 16-18
B10: 18-20 | D10: 2M/ | F10: 2M | J10: 2M/2M | K10: 3e ST | L10: 4r RC | M10: 2M/ 4r FD | P10: 1M©/1M | R10: 4e RCS | U10: 3r SBC L/P | V10: 2M | X10: 3r IS | AA10: |1raut | AB10: 18-20
B11: 20-22 | D11: 2M/ | F11: 2M | J11: 2M/2M | M11: 2M/ | P11: 1M©/ | S11: 3r IS recon./ | V11: 2M
B12: ORA | C12: 302 | D12: 303 | E12: 304 | F12: 305 | G12: 305 B | H12: 308 | I12: 309 | J12: 310 | K12: 505 | L12: 505B | M12: S35 | N12: G6 | O12: G2 | P12: C01 | R12: C12 | S12: C13 | T12: sala 7 Obs | U12: BT 6.01 Lab Bosch | V12: BT 6.03 | W12: BT 6.04 | X12: BT 6.05 | Y12: 320 (BCE) | Z12: 329 (LEC) | AA12: 192 (Fizica) | AB12: ORA
A13: MARŢI | B13: 8:-10: | C13: 3r SDED | D13: 2r ED | E13: 4r SCPC | F13: 3r IRA | G13: 3r EP | I13: 1e FCS | J13: 1e FCS | K13: 3r TS | L13: 4e CN | M13: 4e RD | P13: 3e SI L | R13: 4r SCR | S13: 3r IS Prec /3e SI(P) | X13: 3r IS | AA13: 1r aut | AB13: 8:-10: | AC13: MARŢI
B14: 10:-12: | D14: 2r ED | E14: 4r SCPC | F14: 3r IRA | G14: 3r EP | I14: 1r BCS | J14: 1r BCS | K14: 3r TS | L14: 4e CN | M14: 4e RD | N14: 4r SCD(P) | P14: 3e SI L | R14: 4r SCR | S14: 3e SI (P) | W14: 20.10 11-13 | X14: 3r IS | AA14: 1r aut | AB14: 10:-12:
B15: 12:- 14: | D15: 2r ED | E15: 4r SCPC | F15: 3r IRA | I15: 1r BCS | J15: 1r BCS | K15: 3r TS | M15: 4r FD | P15: 3e SI L | R15: 4r SCR | S15: 3r IS Lrec | U15: 3r SBC L/P | V15: 1e CPPL | W15: 20.10 11-13 | X15: 3r IS | AB15: 12:- 14:
B16: 14-16 | D16: 4r MAD/ | E16: 4r SCPC | F16: 3r IRA | K16: 3r TS | M16: 4r FD | S16: 4r SCR (P) | U16: 3r SBC L/P | V16: 1e CPPL | AB16: 14-16
B17: 16-18 | C17: 3r SDED | D17: 4r MAD/ | F17: 3r IRA | H17: 1M | L17: 4e CN | M17: 4r FD | P17: 1M CPS | R17: 4r SCR | S17: 4r SCR (P) | AB17: 16-18
B18: 18-20 | D18: 1M&2M©/1M | H18: 1M | I18: 2M/ | J18: 1M | L18: 4e CN | M18: 4rFD | P18: 1M CPS | R18: 4r SCR | S18: 4r SCR (P) | U18: 3e KBS | V18: /2M | W18: 2M/ | AB18: 18-20
B19: 20-22 | D19: 1M&2M©/1M | H19: 1M | I19: 2M/ | J19: 1M | P19: 1M CPS| | V19: /2M | W19: 2M/
B20: ORA | C20: 302 | D20: 303 | E20: 304 | F20: 305 | G20: 305 B | H20: 308 | I20: 309 | J20: 310 | K20: 505 | L20: 505B | M20: S35 | N20: G6 | O20: G2 | P20: C01 | R20: C12 | S20: C13 | T20: sala 7 Obs | U20: BT 6.01 Lab Bosch | V20: BT 6.03 | W20: BT 6.04 | X20: BT 6.05 | Y20: 320 (BCE) | Z20: 329 (LEC) | AA20: 192 (Fizica) | AB20: ORA
A21: MIERCURI | B21: 8:-10: | D21: 4r MAD/4e | E21: 4eCPC/4rSCPC | H21: 4r MP | I21: 1r BCS | J21: 1r BCS | M21: 4e RD | N21: 4r SCD | P21: 2r MP | R21: 4e RCS | S21: /4e RCS(P) | X21: 4e PM | Y21: 1r aut | AB21: 8:-10: | AC21: MIERCURI
B22: 10:-12: | D22: 4r MAD/4e | E22: 4eCPC/4rSCPC | H22: 4r MP | I22: 1r BCS | J22: 1r BCS | M22: 4e RD | N22: 4r SCD | P22: 2r MP | R22: 4e RCS | S22: 4e RCS(P) | V22: 1e CPPL | X22: 4e PM | Y22: 1r aut | AA22: 1r aut | AB22: 10:-12:
B23: 12:- 14: | D23: 4r MAD/4e | E23: 4e /4r SCPC | H23: /4r MP | I23: 1r BCS | K23: 2e PM | L23: /4r RC | M23: 4e RD | N23: 4r SCD | P23: 2r MP | R23: 4e RCS | S23: 4eRCS P/4r SCR P | V23: 1e CPPL | AA23: 1e aut | AB23: 12:- 14:
B24: 14-16 | D24: 4r MAD/4e | E24: 4e /4r SCPC | H24: /4r Mp | K24: 2e PM | L24: /4r RC | M24: 4e RD | N24: 4e DCS | P24: 2r MP | R24: 4e RCS | S24: 4r SCR (P) | X24: 3e DSDE | Y24: 1r aut | AB24: 14-16
B25: 16-18 | D25: 2r ED | E25: /4r SCPC | F25: 3e CE | H25: 1M | I25: 3r SDED | M25: 4r FD | N25: 4e DCS | R25: 4r SCR | S25: 4r SCR (P)/1M | X25: 3e DSDE | AB25: 16-18
B26: 18-20 | D26: 2M SI/SR | E26: /4r SCPC | F26: 3e CE | G26: 1M/1M© | H26: 1M | I26: 3r SDED | J26: 2M | K26: 2M/ | M26: 4r FD | N26: 4e DCS P/L | P26: /2M | R26: 4r SCR | S26: 4r SCR (P)/1M | V26: 2M | W26: 2M | AB26: 18-20
B27: 20-22 | C27: 1M | D27: 2M SI/SR | G27: 1M/1M© | H27: 1M | J27: 2M | K27: 2M/ | P27: /2M | R27: /2M | S27: /1M | V27: 2M | W27: 2M | AB27: 20-22
B28: ORA | C28: 302 | D28: 303 | E28: 304 | F28: 305 | G28: 305 B | H28: 308 | I28: 309 | J28: 310 | K28: 505 | L28: 505B | M28: S35 | N28: G6 | O28: G2 | P28: C01 | R28: C12 | S28: C13 | T28: sala 7 Obs | U28: BT 6.01 Lab Bosch | V28: BT 6.03 | W28: BT 6.04 | X28: BT 6.05 | Y28: 320 (BCE) | Z28: 329 (LEC) | AA28: 192 (Fizica) | AB28: ORA
A29: JOI | B29: 8:-10: | D29: 2e DE | E29: 4eCPC / 4rSCPC | F29: 3r IRA | G29: 3e PE | K29: 3e ST | M29: 4r FD | R29: 4r SCR | S29: 3r IS | T29: 4r MEA | U29: 3r IS | V29: 3r IS(P) | W29: 3r TS | X29: 4e PM | Y29: 1r aut | AB29: 8:-10: | AC29: JOI
B30: 10:-12: | D30: 2e DE | E30: 4eCPC/ 4rSCPC | F30: 3r IRA | G30: 3e PE | H30: 1r BCS | K30: 3e ST | M30: 4r FD | N30: 4e DCS L/(P) | R30: 4r SCR | S30: 3r IS | T30: 4r MEA | U30: 3e KBS/ | V30: 3r IS(P) | W30: 3r TS | X30: 4e PM | Y30: 1r aut | AB30: 10:-12:
B31: 12:- 14: | D31: 2e DE | F31: 3e CE | K31: 3e ST | R31: 4r SCR | U31: 3e KBS/ | V31: 3r IS(P) | X31: AD | AB31: 12:- 14:
B32: 14-16 | D32: 2e DE | E32: 4e CPC/ | K32: /3e ST S | N32: 4e DCS(P) | U32: AD | V32: /2M | Z32: 1e LEC | AB32: 14-16
B33: 16-18 | C33: 3r SDED | D33: 2e DE | E33: 4e CPC/ | H33: postuniv/ | L33: 3r SDED | N33: 4e DCS(P) | R33: 3r IS | S33: 1M/ | U33: 3e KBS/ | V33: 2M | X33: 1e FCS | Z33: 1e LEC | AB33: 16-18
B34: 18-20 | C34: /1M | D34: 1M/1M© | E34: /2M© | H34: postuniv/ 2M | I34: 3r SDED | J34: 2M©//4e CPC P | K34: 2M | L34: 3r SDED | M34: 1M | P34: /4r SCR(P) | R34: 3r IS | S34: 1M/ | U34: 3e KBS/ | V34: /2M | W34: /2M | Z34: 1e LEC | AB34: 18-20
B35: 20-22 | C35: /1M | D35: 1M/1M© | E35: /2M | H35: postuniv/ 2M | J35: 2M©/ | K35: 2M | M35: 1M | S35: 1M/ | V35: /2M | W35: /2M | X35: /2M | AB35: 20-22
B36: ORA | C36: 302 | D36: 303 | E36: 304 | F36: 305 | G36: 305 B | H36: 308 | I36: 309 | J36: 310 | K36: 505 | L36: 505B | M36: S35 | N36: G6 | O36: G2 | P36: C01 | R36: C12 | S36: C13 | T36: sala 7 Obs | U36: BT 6.01 Lab Bosch | V36: BT 6.03 | W36: BT 6.04 | X36: BT 6.05 | Y36: 320 (BCE) | Z36: 329 (LEC) | AA36: 192 (Fizica) | AB36: ORA
A37: VINERI | B37: 8:-10: | D37: 4r MAD | E37: 4r SCPC(P) | I37: 1e FCS | J37: 4r SCD(P) | K37: 2e PM | T37: 4r MEA | V37: 1e CPPL | AA37: 1r aut | AB37: 8:-10: | AC37: VINERI
B38: 10:-12: | D38: 4r MAD | E38: 4r SCPC(P) | I38: 1e FCS | J38: 4r SCD(P) | K38: 2e PM | T38: 4r MEA | V38: 1e CPPL | Y38: 1r aut | AA38: 1r aut | AB38: 10:-12:
B39: 12:- 14: | D39: 4r SCPC(P) | E39: 4r SCPC(P) | I39: 1e FCS | J39: 4r SCD(P) | K39: 2e PM | U39: AD | AA39: 1r aut | AB39: 12:- 14:
B40: 14-16 | C40: 4e CPC(P) | D40: 4r SCPC(P) | E40: 4e CPC | H40: 2M/ | J40: 4r SCD(P) | U40: AD | Y40: 1r aut | AB40: 14-16
B41: 16-18 | C41: 1M/4e CPC(P) | D41: 4r SCPC(P) | E41: 4e CPC | H41: 2M | J41: 4r SCD(P) | P41: 2M/ | AB41: 16-18
...

Sheet Master CAP 31112
A1: UNIVERSITATEA TEHNICA din CLUJ-NAPOCA
A2: Facultatea Automatica si Calculatoare
A3: Domeniul: Inginerie Sistemelor Automate Grupa 31112
G4: Grupa 31112
A6: O R A R Master CAP (semestrul I 2010-2011)
A9: Ora | B9: LUNI | D9: MARTI | F9: MIERCURI | H9: JOI | J9: VINERI | L9: SAMBATA
A10: Saptamana 1: 27.09.10 - 3.10.10
A11: 9-11 | N11: 1
A12: 11-13
A13: 13-15
A14: 15-17 | H14: CI (L) | M14: CI (L)
A15: 17-19
A16: 19-21 | O16: SAMBATA
A17: Saptamana 2: 4.10.10 - 10.10.10 | P17: CI L | Q17: 1
A18: 9-11 | L18: VA (L) | N18: 2 | P18: VA L | Q18: 2,5, 9,14
A19: 11-13 | P19: SH L | Q19: 3,7,12,14
A20: 13-15 | M20: VA (L) | P20: MCP L | Q20: 4,8,10,13
A21: 15-17
A22: 17-19
A23: 19-21
A24: Saptamana 3: 11.10.10 - 17.10.10
A25: 9-11 | L25: SH (L) | N25: 3
A26: 11-13
A27: 13-15 | M27: SH (L)
A28: 15-17
A29: 17-19
A30: 19-21
A31: Saptamana 4: 18.10.10 - 24.10.10
A32: \ | L32: MCP(L) | N32: 4
A33: 11-13
A34: 13-15 | M34: MCP (L)
A35: 15-17
A36: 17-19
A37: 19-21
A38: Saptamana 5: 25.10.10 - 31.10.10
A39: 9-11 | L39: VA (L) | N39: 5
A40: 11-13
A41: 13-15 | M41: VA (L)
A42: 15-17
A43: 17-19
...

Sheet sablon
C1: Aut | D1: Calc
A2: Luni | B2: 08-10
B3: 10-12
B4: 12-14
B5: 14-16
B6: 16-18
B7: 18-20
A8: Marti | B8: 08-10
B9: 10-12
B10: 12-14
B11: 14-16
B12: 16-18
B13: 18-20
A14: Miercuri | B14: 08-10
B15: 10-12
B16: 12-14
B17: 14-16
B18: 16-18
B19: 18-20
A20: Joi | B20: 08-10
B21: 10-12
B22: 12-14
B23: 14-16
B24: 16-18
B25: 18-20
A26: Vineri | B26: 08-10
B27: 10-12
B28: 12-14
B29: 14-16
B30: 16-18
B31: 18-20

Sheet Sheet2
C24: Saptamana
A25: pt 31162
B26: VA L | C26: 2,5, 9,14*; sambata, semigr. 1 intre 9-13 si semigr.2 13-17 | E26: *in sapt.14, semigrupa 1, intre 9-11
E28: in sapt 14 semigrupa 1 intre 11-13
B30: SH L | C30: 3,7,12,14* sambata, semigr. 1 intre 9-13 si semigr.2 13-17 | E30: *in sapt.14, semigrupa 1, intre 11-13
E32: in sapt 14 semigrupa 1 intre 9-11
B34: CI | C34: 1,6,11 joi semigr. 1 si sambata semigr. 2 intre 15 -19 | E34: luni semigr. 1 si marti semigr. 2 doar in sapt 14 intre 19-21
B38: MCP L | C38: 4,8,10,13*; in saptamanile 4,8,10 sambata, semigr. 1 intre 9-13 si semigr.2 13-17 | E38: *in sapt. 13, semigrupa 1: 9-11, semigrupa 2: 11-13
